#include <iostream>
#include <utility> // For std::pair, std::make_pair, std::move, std::move_if_noexcept
#include <stdexcept> // std::runtime_error



class MoveClass
{
private:
    int* m_resource{};

public:
    MoveClass() = default;

    MoveClass(int resource)
        : m_resource{ new int{ resource } }
    {
    }

    // Copy constructor
    MoveClass(const MoveClass& that)
    {
        // deep copy
        if (that.m_resource != nullptr)
        {
            m_resource = new int{ *that.m_resource };
        }
    }

    // Move constructor
    MoveClass(MoveClass&& that) noexcept
        : m_resource{ that.m_resource }
    {
        that.m_resource = nullptr;
    }

    ~MoveClass()
    {
        std::cout << "destroying " << *this << '\n';

        delete m_resource;
    }

    friend std::ostream& operator<<(std::ostream& out, const MoveClass& moveClass)
    {
        out << "MoveClass(";

        if (moveClass.m_resource == nullptr)
        {
            out << "empty";
        }
        else
        {
            out << *moveClass.m_resource;
        }

        out << ')';

        return out;
    }
};


class CopyClass
{
public:
    bool m_throw{};

    CopyClass() = default;

    // Copy constructor throws an exception when copying from
    // a CopyClass object where its m_throw is 'true'
    CopyClass(const CopyClass& that)
        : m_throw{ that.m_throw }
    {
        if (m_throw)
        {
            throw std::runtime_error{ "abort!" };
        }
    }
};

int main()
{
    // We can make a std::pair without any problems:
    std::pair my_pair{ MoveClass{ 13 }, CopyClass{} };

    std::cout << "my_pair.first: " << my_pair.first << '\n';

    // But the problem arises when we try to move that pair into another pair.
    try
    {
        my_pair.second.m_throw = true; // To trigger copy constructor exception

        // The following line will throw an exception
        //std::pair moved_pair{ std::move(my_pair) }; // damage risk
        std::pair moved_pair{ std::move_if_noexcept(my_pair) }; // fix for the std move

        std::cout << "moved pair exists\n"; // Never prints
    }
    catch (const std::exception& ex)
    {
        std::cerr << "Error found: " << ex.what() << '\n';
    }

    std::cout << "my_pair.first: " << my_pair.first << '\n';

    return 0;
}